<?xml version="1.0"?>
<robot name="line_following_robot">

  <!-- Base Link -->
  <link name="base_link"> <!--Pusat robot berbentuk silinder dengan warna biru-->
    <visual>
      <geometry>
        <cylinder radius="0.2" length="0.1"/>
      </geometry>
      <material name="blue"/>
    </visual>
    <collision>
      <geometry>
        <cylinder radius="0.2" length="0.1"/>
      </geometry>
    </collision>
  </link>

  <!-- Wheels -->
  <link name="left_rear_wheel">
    <visual>
      <geometry>
        <cylinder radius="0.1" length="0.05"/>
      </geometry>
    </visual>
    <collision>
      <geometry>
        <cylinder radius="0.1" length="0.05"/>
      </geometry>
    </collision>
  </link>

  <link name="right_rear_wheel">
    <visual>
      <geometry>
        <cylinder radius="0.1" length="0.05"/>
      </geometry>
    </visual>
    <collision>
      <geometry>
        <cylinder radius="0.1" length="0.05"/>
      </geometry>
    </collision>
  </link>

  <link name="left_front_wheel">
    <visual>
      <geometry>
        <cylinder radius="0.1" length="0.05"/>
      </geometry>
    </visual>
    <collision>
      <geometry>
        <cylinder radius="0.1" length="0.05"/>
      </geometry>
    </collision>
  </link>

  <link name="right_front_wheel">
    <visual>
      <geometry>
        <cylinder radius="0.1" length="0.05"/>
      </geometry>
    </visual>
    <collision>
      <geometry>
        <cylinder radius="0.1" length="0.05"/>
      </geometry>
    </collision>
  </link>

  <!-- Joint between base and wheels -->
  <joint name="left_rear_wheel_joint" type="revolute"> <!--Revolute -> Sambungan berputar (rotasi), seperti roda-->
    <parent link="base_link"/>
    <child link="left_wheel"/>
    <origin xyz="-0.15 -0.1 0" rpy="0 0 0"/>
    <axis xyz="0 1 0"/>
    <limit effort="100" velocity="10" lower="0" upper="3.14"/>
  </joint>

  <joint name="right_rear_wheel_joint" type="revolute">
    <parent link="base_link"/>
    <child link="right_wheel"/>
    <origin xyz="-0.15 0.1 0" rpy="0 0 0"/>
    <axis xyz="0 1 0"/>
    <limit effort="100" velocity="10" lower="0" upper="3.14"/>
    <!--Effort -> batas tenaga maksimum (100 unit)-->
    <!--Velocity -> Kecepatan maksimum (10 rad/s)-->
    <!--Lower dan Upper -> Batas rotasi dalam radian, dari 0 hingga 3.14 (setengah putaran)-->
  </joint>

  <joint name="left_front_wheel_joint" type="revolute">
    <parent link="base_link"/>
    <child link="left_front_wheel"/>
    <origin xyz="0.15 -0.1 0" rpy="0 0 0"/>
    <axis xyz="0 1 0"/>
    <limit effort="100" velocity="10" lower="0" upper="3.14"/>
  </joint>

  <joint name="right_front_wheel_joint" type="revolute">
    <parent link="base_link"/>
    <child link="right_front_wheel"/>
    <origin xyz="-0.15 0.1 0" rpy="0 0 0"/>
    <axis xyz="0 1 0"/>
    <limit effort="100" velocity="10" lower="0" upper="3.14"/>
  </joint>

</robot>
